Пользователь 636728683 вызвал команду /start
Пользователь 636728683 вызвал команду 'Задать ссылку'.
Пользователь ввёл неправильную ссылку <class 'requests.exceptions.MissingSchema'>
Traceback (most recent call last):
  File "/home/bigsmirnovsky/Документы/projects/4_async_bot/main.py", line 113, in process_url
    check = requests.head(url_text)
  File "/home/bigsmirnovsky/Документы/projects/4_async_bot/async_bot_env/lib/python3.10/site-packages/requests/api.py", line 100, in head
    return request("head", url, **kwargs)
  File "/home/bigsmirnovsky/Документы/projects/4_async_bot/async_bot_env/lib/python3.10/site-packages/requests/api.py", line 59, in request
    return session.request(method=method, url=url, **kwargs)
  File "/home/bigsmirnovsky/Документы/projects/4_async_bot/async_bot_env/lib/python3.10/site-packages/requests/sessions.py", line 575, in request
    prep = self.prepare_request(req)
  File "/home/bigsmirnovsky/Документы/projects/4_async_bot/async_bot_env/lib/python3.10/site-packages/requests/sessions.py", line 486, in prepare_request
    p.prepare(
  File "/home/bigsmirnovsky/Документы/projects/4_async_bot/async_bot_env/lib/python3.10/site-packages/requests/models.py", line 368, in prepare
    self.prepare_url(url, params)
  File "/home/bigsmirnovsky/Документы/projects/4_async_bot/async_bot_env/lib/python3.10/site-packages/requests/models.py", line 439, in prepare_url
    raise MissingSchema(
requests.exceptions.MissingSchema: Invalid URL 'фыцвфв': No scheme supplied. Perhaps you meant https://фыцвфв?
Пользователь 636728683 вызвал команду 'Задать ссылку'.
Пользователь 636728683 вызвал команду 'Остановить'.
